Workbook

Sheet current_products_edited
A1: Product No. | B1: ProductName | C1: Company No. | D1: Registration Status | E1: Appl No. | F1: Appl Status | G1: Auth Type | H1: Received Date | I1: Reviewer | J1: PRODUCT TYPE | K1: is_PDF_downloaded | L1: sub | M1: concat | N1: lookip | O1: isdownloaded2 | P1: =COUNTIF(N:N,"FALSE") -> 672
A2: 100-1098 | B2: QUADRIS FLOWABLE FUNGICIDE (2EE - DOWNY MILDEW) | C2: 00COR | D2: REGISTERED | E2: 15982 | F2: CLOSED | G2: 2EE | H2: 40036 | J2: FUNGICIDE | K2: TRUE | L2: =SUBSTITUTE(LOWER(SUBSTITUTE(SUBSTITUTE(SUBSTITUTE(B2," ",""),"/",""),"&","")),"and","") -> quadrisflowablefungicide(2ee-downymildew) | M2: =_xlfn.CONCAT(L2,A2) -> quadrisflowablefungicide(2ee-downymildew)100-1098 | N2: =IFERROR(VLOOKUP(LOWER(M2),file_list!$B:$B,1,FALSE),FALSE) -> quadrisflowablefungicide(2ee-downymildew)100-1098 | O2: =IF(N2=FALSE,"FALSE","TRUE") -> TRUE
A3: 264-827 | B3: ADMIRE PRO SYSTEMIC PROTECTANT (2EE - SWEDE MIDGE) | C3: 00COR | D3: REGISTERED | E3: 14441 | F3: CLOSED | G3: 2EE | H3: 39864 | J3: INSECTICIDE | K3: TRUE | L3: =SUBSTITUTE(LOWER(SUBSTITUTE(SUBSTITUTE(SUBSTITUTE(B3," ",""),"/",""),"&","")),"and","") -> admireprosystemicprotectant(2ee-swedemidge) | M3: =_xlfn.CONCAT(L3,A3) -> admireprosystemicprotectant(2ee-swedemidge)264-827 | N3: =IFERROR(VLOOKUP(LOWER(M3),file_list!$B:$B,1,FALSE),FALSE) -> admireprosystemicprotectant(2ee-swedemidge)264-827 | O3: =IF(N3=FALSE,"FALSE","TRUE") -> TRUE
A4: 55146-64 | B4: CHAMP FORMULA 2 FLOWABLE [UNRESTRICTED AS OF 9/21/2005] (2EE - PHYTOPHORA BLIGHT IN PEPPER) | C4: 00COR | D4: REGISTERED | E4: 5681 | F4: CLOSED | G4: 2EE | H4: 38903 | J4: FUNGICIDE | K4: FALSE | L4: =SUBSTITUTE(LOWER(SUBSTITUTE(SUBSTITUTE(SUBSTITUTE(B4," ",""),"/",""),"&","")),"and","") -> champformula2flowable[unrestrictedasof9212005](2ee-phytophorablightinpepper) | M4: =_xlfn.CONCAT(L4,A4) -> champformula2flowable[unrestrictedasof9212005](2ee-phytophorablightinpepper)55146-64 | N4: =IFERROR(VLOOKUP(LOWER(M4),file_list!$B:$B,1,FALSE),FALSE) -> champformula2flowable[unrestrictedasof9212005](2ee-phytophorablightinpepper)55146-64 | O4: =IF(N4=FALSE,"FALSE","TRUE") -> TRUE
A5: 55146-64 | B5: CHAMP FORMULA 2 FLOWABLE (2EE - PHYTOPHTHORA BLIGHT IN CUCURBIT) | C5: 00COR | D5: REGISTERED | E5: 4999 | F5: CLOSED | G5: 2EE | H5: 38817 | J5: FUNGICIDE | K5: TRUE | L5: =SUBSTITUTE(LOWER(SUBSTITUTE(SUBSTITUTE(SUBSTITUTE(B5," ",""),"/",""),"&","")),"and","") -> champformula2flowable(2ee-phytophthorablightincucurbit) | M5: =_xlfn.CONCAT(L5,A5) -> champformula2flowable(2ee-phytophthorablightincucurbit)55146-64 | N5: =IFERROR(VLOOKUP(LOWER(M5),file_list!$B:$B,1,FALSE),FALSE) -> champformula2flowable(2ee-phytophthorablightincucurbit)55146-64 | O5: =IF(N5=FALSE,"FALSE","TRUE") -> TRUE
A6: 100-1295 | B6: WARRIOR II WITH ZEON TECHNOLOGY (25 FOOT BUFFER STRIP TO COASTAL MARSHES) (2EE - LEEK MOTH) | C6: 00USDA | D6: REGISTERED | E6: 19181 | F6: CLOSED | G6: 2EE | H6: 40367 | J6: INSECTICIDE | K6: TRUE | L6: =SUBSTITUTE(LOWER(SUBSTITUTE(SUBSTITUTE(SUBSTITUTE(B6," ",""),"/",""),"&","")),"and","") -> warrioriiwithzeontechnology(25footbufferstriptocoastalmarshes)(2ee-leekmoth) | M6: =_xlfn.CONCAT(L6,A6) -> warrioriiwithzeontechnology(25footbufferstriptocoastalmarshes)(2ee-leekmoth)100-1295 | N6: =IFERROR(VLOOKUP(LOWER(M6),file_list!$B:$B,1,FALSE),FALSE) -> warrioriiwithzeontechnology(25footbufferstriptocoastalmarshes)(2ee-leekmoth)100-1295 | O6: =IF(N6=FALSE,"FALSE","TRUE") -> TRUE
A7: 352-384 | B7: DUPONT LANNATE LV INSECTICIDE (2EE - LEEK MOTH) | C7: 00USDA | D7: REGISTERED | E7: 19181 | F7: CLOSED | G7: 2EE | H7: 40367 | J7: INSECTICIDE | K7: TRUE | L7: =SUBSTITUTE(LOWER(SUBSTITUTE(SUBSTITUTE(SUBSTITUTE(B7," ",""),"/",""),"&","")),"and","") -> dupontlannatelvinsecticide(2ee-leekmoth) | M7: =_xlfn.CONCAT(L7,A7) -> dupontlannatelvinsecticide(2ee-leekmoth)352-384 | N7: =IFERROR(VLOOKUP(LOWER(M7),file_list!$B:$B,1,FALSE),FALSE) -> dupontlannatelvinsecticide(2ee-leekmoth)352-384 | O7: =IF(N7=FALSE,"FALSE","TRUE") -> TRUE
A8: 62719-282 | B8: ENTRUST (2EE - LEEK MOTH) | C8: 00USDA | D8: REGISTERED | E8: 19181 | F8: CLOSED | G8: 2EE | H8: 40367 | J8: INSECTICIDE | K8: TRUE | L8: =SUBSTITUTE(LOWER(SUBSTITUTE(SUBSTITUTE(SUBSTITUTE(B8," ",""),"/",""),"&","")),"and","") -> entrust(2ee-leekmoth) | M8: =_xlfn.CONCAT(L8,A8) -> entrust(2ee-leekmoth)62719-282 | N8: =IFERROR(VLOOKUP(LOWER(M8),file_list!$B:$B,1,FALSE),FALSE) -> entrust(2ee-leekmoth)62719-282 | O8: =IF(N8=FALSE,"FALSE","TRUE") -> TRUE
A9: 62719-545 | B9: RADIANT SC (2EE - LEEK MOTH) | C9: 00USDA | D9: REGISTERED | E9: 19181 | F9: CLOSED | G9: 2EE | H9: 40367 | J9: INSECTICIDE | K9: TRUE | L9: =SUBSTITUTE(LOWER(SUBSTITUTE(SUBSTITUTE(SUBSTITUTE(B9," ",""),"/",""),"&","")),"and","") -> radiantsc(2ee-leekmoth) | M9: =_xlfn.CONCAT(L9,A9) -> radiantsc(2ee-leekmoth)62719-545 | N9: =IFERROR(VLOOKUP(LOWER(M9),file_list!$B:$B,1,FALSE),FALSE) -> radiantsc(2ee-leekmoth)62719-545 | O9: =IF(N9=FALSE,"FALSE","TRUE") -> TRUE
A10: 73049-39 | B10: DIPEL DF DRY FLOWABLE BIOLOGICAL INSECTICIDE (2EE - LEEK MOTH) | C10: 00USDA | D10: REGISTERED | E10: 19181 | F10: CLOSED | G10: 2EE | H10: 40367 | J10: INSECTICIDE | K10: TRUE | L10: =SUBSTITUTE(LOWER(SUBSTITUTE(SUBSTITUTE(SUBSTITUTE(B10," ",""),"/",""),"&","")),"and","") -> dipeldfdryflowablebiologicalinsecticide(2ee-leekmoth) | M10: =_xlfn.CONCAT(L10,A10) -> dipeldfdryflowablebiologicalinsecticide(2ee-leekmoth)73049-39 | N10: =IFERROR(VLOOKUP(LOWER(M10),file_list!$B:$B,1,FALSE),FALSE) -> dipeldfdryflowablebiologicalinsecticide(2ee-leekmoth)73049-39 | O10: =IF(N10=FALSE,"FALSE","TRUE") -> TRUE
A11: 100-1000 | B11: DEMON WP INSECTICIDE IN WATER SOLUBLE PACKETS | C11: 100 | D11: REGISTERED | E11: 1288082 | F11: CLOSED | G11: ROUTINE | H11: 45604 | I11: KATHERINE HETTER | J11: INSECTICIDE | K11: TRUE | L11: =SUBSTITUTE(LOWER(SUBSTITUTE(SUBSTITUTE(SUBSTITUTE(B11," ",""),"/",""),"&","")),"and","") -> demonwpinsecticideinwatersolublepackets | M11: =_xlfn.CONCAT(L11,A11) -> demonwpinsecticideinwatersolublepackets100-1000 | N11: =IFERROR(VLOOKUP(LOWER(M11),file_list!$B:$B,1,FALSE),FALSE) -> demonwpinsecticideinwatersolublepackets100-1000 | O11: =IF(N11=FALSE,"FALSE","TRUE") -> TRUE
A12: 100-1014 | B12: TRIMMIT 2SC PLANT GROWTH REGULATOR | C12: 100 | D12: REGISTERED | E12: 1288082 | F12: CLOSED | G12: ROUTINE | H12: 45604 | I12: KATHERINE HETTER | J12: GROWTH REGULATOR | K12: TRUE | L12: =SUBSTITUTE(LOWER(SUBSTITUTE(SUBSTITUTE(SUBSTITUTE(B12," ",""),"/",""),"&","")),"and","") -> trimmit2scplantgrowthregulator | M12: =_xlfn.CONCAT(L12,A12) -> trimmit2scplantgrowthregulator100-1014 | N12: =IFERROR(VLOOKUP(LOWER(M12),file_list!$B:$B,1,FALSE),FALSE) -> trimmit2scplantgrowthregulator100-1014 | O12: =IF(N12=FALSE,"FALSE","TRUE") -> TRUE
A13: 100-1050 | B13: TALON-G RODENTICIDE BAIT PACK MINI-PELLETS CONTAINS BITREX | C13: 100 | D13: REGISTERED | E13: 1288082 | F13: CLOSED | G13: ROUTINE | H13: 45604 | I13: KATHERINE HETTER | J13: RODENTICIDE | K13: TRUE | L13: =SUBSTITUTE(LOWER(SUBSTITUTE(SUBSTITUTE(SUBSTITUTE(B13," ",""),"/",""),"&","")),"and","") -> talon-grodenticidebaitpackmini-pelletscontainsbitrex | M13: =_xlfn.CONCAT(L13,A13) -> talon-grodenticidebaitpackmini-pelletscontainsbitrex100-1050 | N13: =IFERROR(VLOOKUP(LOWER(M13),file_list!$B:$B,1,FALSE),FALSE) -> talon-grodenticidebaitpackmini-pelletscontainsbitrex100-1050 | O13: =IF(N13=FALSE,"FALSE","TRUE") -> TRUE
A14: 100-1055 | B14: TALON WEATHERBLOK XT | C14: 100 | D14: REGISTERED | E14: 1288082 | F14: CLOSED | G14: ROUTINE | H14: 45604 | I14: KATHERINE HETTER | J14: RODENTICIDE | K14: TRUE | L14: =SUBSTITUTE(LOWER(SUBSTITUTE(SUBSTITUTE(SUBSTITUTE(B14," ",""),"/",""),"&","")),"and","") -> talonweatherblokxt | M14: =_xlfn.CONCAT(L14,A14) -> talonweatherblokxt100-1055 | N14: =IFERROR(VLOOKUP(LOWER(M14),file_list!$B:$B,1,FALSE),FALSE) -> talonweatherblokxt100-1055 | O14: =IF(N14=FALSE,"FALSE","TRUE") -> TRUE
A15: 100-1061 | B15: REGLONE DESICCANT | C15: 100 | D15: REGISTERED | E15: 1288082 | F15: CLOSED | G15: ROUTINE | H15: 45604 | I15: KATHERINE HETTER | J15: HERBICIDE | K15: TRUE | L15: =SUBSTITUTE(LOWER(SUBSTITUTE(SUBSTITUTE(SUBSTITUTE(B15," ",""),"/",""),"&","")),"and","") -> reglonedesiccant | M15: =_xlfn.CONCAT(L15,A15) -> reglonedesiccant100-1061 | N15: =IFERROR(VLOOKUP(LOWER(M15),file_list!$B:$B,1,FALSE),FALSE) -> reglonedesiccant100-1061 | O15: =IF(N15=FALSE,"FALSE","TRUE") -> TRUE
A16: 100-1063 | B16: REWARD MANUFACTURING CONCENTRATE | C16: 100 | D16: REGISTERED | E16: 1288082 | F16: CLOSED | G16: ROUTINE | H16: 45604 | I16: KATHERINE HETTER | J16: HERBICIDE | K16: TRUE | L16: =SUBSTITUTE(LOWER(SUBSTITUTE(SUBSTITUTE(SUBSTITUTE(B16," ",""),"/",""),"&","")),"and","") -> rewardmanufacturingconcentrate | M16: =_xlfn.CONCAT(L16,A16) -> rewardmanufacturingconcentrate100-1063 | N16: =IFERROR(VLOOKUP(LOWER(M16),file_list!$B:$B,1,FALSE),FALSE) -> rewardmanufacturingconcentrate100-1063 | O16: =IF(N16=FALSE,"FALSE","TRUE") -> TRUE
A17: 100-1066 | B17: DEMAND CS INSECTICIDE (NO USE WITHIN 100 FT. OF COASTAL MARSHES) (2ee - brown marmorated stink bug/kudzu stink bug) | C17: 100 | D17: REGISTERED | E17: 1197077 | F17: CLOSED | G17: 2EE | H17: 43983 | I17: SHAUN PETERSON | J17: INSECTICIDE | K17: FALSE | L17: =SUBSTITUTE(LOWER(SUBSTITUTE(SUBSTITUTE(SUBSTITUTE(B17," ",""),"/",""),"&","")),"and","") -> demcsinsecticide(nousewithin100ft.ofcoastalmarshes)(2ee-brownmarmoratedstinkbugkudzustinkbug) | M17: =_xlfn.CONCAT(L17,A17) -> demcsinsecticide(nousewithin100ft.ofcoastalmarshes)(2ee-brownmarmoratedstinkbugkudzustinkbug)100-1066 | N17: =IFERROR(VLOOKUP(LOWER(M17),file_list!$B:$B,1,FALSE),FALSE) -> demcsinsecticide(nousewithin100ft.ofcoastalmarshes)(2ee-brownmarmoratedstinkbugkudzustinkbug)100-1066 | O17: =IF(N17=FALSE,"FALSE","TRUE") -> TRUE
A18: 100-1066 | B18: DEMAND CS INSECTICIDE (NO USE WITHIN 100 FT. OF COASTAL MARSHES) | C18: 100 | D18: REGISTERED | E18: 1288082 | F18: CLOSED | G18: ROUTINE | H18: 45604 | I18: KATHERINE HETTER | J18: INSECTICIDE | K18: TRUE | L18: =SUBSTITUTE(LOWER(SUBSTITUTE(SUBSTITUTE(SUBSTITUTE(B18," ",""),"/",""),"&","")),"and","") -> demcsinsecticide(nousewithin100ft.ofcoastalmarshes) | M18: =_xlfn.CONCAT(L18,A18) -> demcsinsecticide(nousewithin100ft.ofcoastalmarshes)100-1066 | N18: =IFERROR(VLOOKUP(LOWER(M18),file_list!$B:$B,1,FALSE),FALSE) -> demcsinsecticide(nousewithin100ft.ofcoastalmarshes)100-1066 | O18: =IF(N18=FALSE,"FALSE","TRUE") -> TRUE
A19: 100-1066 | B19: PATROL (2ee - Spotted Lanternfly) | C19: 100 | D19: REGISTERED | E19: 1220455 | F19: CLOSED | G19: 2EE | H19: 44327 | I19: SHAUN PETERSON | J19: INSECTICIDE | K19: TRUE | L19: =SUBSTITUTE(LOWER(SUBSTITUTE(SUBSTITUTE(SUBSTITUTE(B19," ",""),"/",""),"&","")),"and","") -> patrol(2ee-spottedlanternfly) | M19: =_xlfn.CONCAT(L19,A19) -> patrol(2ee-spottedlanternfly)100-1066 | N19: =IFERROR(VLOOKUP(LOWER(M19),file_list!$B:$B,1,FALSE),FALSE) -> patrol(2ee-spottedlanternfly)100-1066 | O19: =IF(N19=FALSE,"FALSE","TRUE") -> TRUE
A20: 100-1066 | B20: DEMAND CS INSECTICIDE (NO USE WITHIN 100 FT. OF COASTAL MARSHES) (2ee - spotted lanternfly) | C20: 100 | D20: REGISTERED | E20: 1189769 | F20: CLOSED | G20: 2EE | H20: 43859 | I20: SHAUN PETERSON | J20: INSECTICIDE | K20: TRUE | L20: =SUBSTITUTE(LOWER(SUBSTITUTE(SUBSTITUTE(SUBSTITUTE(B20," ",""),"/",""),"&","")),"and","") -> demcsinsecticide(nousewithin100ft.ofcoastalmarshes)(2ee-spottedlanternfly) | M20: =_xlfn.CONCAT(L20,A20) -> demcsinsecticide(nousewithin100ft.ofcoastalmarshes)(2ee-spottedlanternfly)100-1066 | N20: =IFERROR(VLOOKUP(LOWER(M20),file_list!$B:$B,1,FALSE),FALSE) -> demcsinsecticide(nousewithin100ft.ofcoastalmarshes)(2ee-spottedlanternfly)100-1066 | O20: =IF(N20=FALSE,"FALSE","TRUE") -> TRUE
A21: 100-1066 | B21: PATROL (NO USE WITHIN 100' OF COASTAL MARSHES IN NYS) (2EE - BROWN MARMORATED STINK BUG AND KUDZU STINK BUG) | C21: 100 | D21: REGISTERED | E21: 22512 | F21: CLOSED | G21: 2EE | H21: 40739 | J21: INSECTICIDE | K21: TRUE | L21: =SUBSTITUTE(LOWER(SUBSTITUTE(SUBSTITUTE(SUBSTITUTE(B21," ",""),"/",""),"&","")),"and","") -> patrol(nousewithin100'ofcoastalmarshesinnys)(2ee-brownmarmoratedstinkbugkudzustinkbug) | M21: =_xlfn.CONCAT(L21,A21) -> patrol(nousewithin100'ofcoastalmarshesinnys)(2ee-brownmarmoratedstinkbugkudzustinkbug)100-1066 | N21: =IFERROR(VLOOKUP(LOWER(M21),file_list!$B:$B,1,FALSE),FALSE) -> patrol(nousewithin100'ofcoastalmarshesinnys)(2ee-brownmarmoratedstinkbugkudzustinkbug)100-1066 | O21: =IF(N21=FALSE,"FALSE","TRUE") -> TRUE
A22: 100-1066 | B22: PATROL (NO USE WITHIN 100' OF COASTAL MARSHES IN NYS) | C22: 100 | D22: REGISTERED | E22: 1288082 | F22: CLOSED | G22: ROUTINE | H22: 45604 | I22: KATHERINE HETTER | J22: INSECTICIDE | K22: TRUE | L22: =SUBSTITUTE(LOWER(SUBSTITUTE(SUBSTITUTE(SUBSTITUTE(B22," ",""),"/",""),"&","")),"and","") -> patrol(nousewithin100'ofcoastalmarshesinnys) | M22: =_xlfn.CONCAT(L22,A22) -> patrol(nousewithin100'ofcoastalmarshesinnys)100-1066 | N22: =IFERROR(VLOOKUP(LOWER(M22),file_list!$B:$B,1,FALSE),FALSE) -> patrol(nousewithin100'ofcoastalmarshesinnys)100-1066 | O22: =IF(N22=FALSE,"FALSE","TRUE") -> TRUE
A23: 100-1066 | B23: BORDER (no app within 100 ft of coastal marsh in ny) | C23: 100 | D23: REGISTERED | E23: 1288082 | F23: CLOSED | G23: ROUTINE | H23: 45604 | I23: KATHERINE HETTER | J23: INSECTICIDE | K23: TRUE | L23: =SUBSTITUTE(LOWER(SUBSTITUTE(SUBSTITUTE(SUBSTITUTE(B23," ",""),"/",""),"&","")),"and","") -> border(noappwithin100ftofcoastalmarshinny) | M23: =_xlfn.CONCAT(L23,A23) -> border(noappwithin100ftofcoastalmarshinny)100-1066 | N23: =IFERROR(VLOOKUP(LOWER(M23),file_list!$B:$B,1,FALSE),FALSE) -> border(noappwithin100ftofcoastalmarshinny)100-1066 | O23: =IF(N23=FALSE,"FALSE","TRUE") -> TRUE
A24: 100-1070 | B24: FUSILADE DX HERBICIDE (NOT FOR SALE, USE, OR DISTRIBUTION IN NASSAU AND SUFFOLK COUNTIES) | C24: 100 | D24: REGISTERED | E24: 1301365 | F24: CLOSED | G24: ROUTINE | H24: 45813 | I24: MATTHEW J GOGIS | J24: HERBICIDE | K24: TRUE | L24: =SUBSTITUTE(LOWER(SUBSTITUTE(SUBSTITUTE(SUBSTITUTE(B24," ",""),"/",""),"&","")),"and","") -> fusiladedxherbicide(notforsale,use,ordistributioninnassausuffolkcounties) | M24: =_xlfn.CONCAT(L24,A24) -> fusiladedxherbicide(notforsale,use,ordistributioninnassausuffolkcounties)100-1070 | N24: =IFERROR(VLOOKUP(LOWER(M24),file_list!$B:$B,1,FALSE),FALSE) -> fusiladedxherbicide(notforsale,use,ordistributioninnassausuffolkcounties)100-1070 | O24: =IF(N24=FALSE,"FALSE","TRUE") -> TRUE
A25: 100-1075 | B25: FORCE 3G INSECTICIDE (NYS MAX RATE 0.164 LB AI/A/YR) | C25: 100 | D25: REGISTERED | E25: 1288082 | F25: CLOSED | G25: ROUTINE | H25: 45604 | I25: KATHERINE HETTER | J25: INSECTICIDE | K25: FALSE | L25: =SUBSTITUTE(LOWER(SUBSTITUTE(SUBSTITUTE(SUBSTITUTE(B25," ",""),"/",""),"&","")),"and","") -> force3ginsecticide(nysmaxrate0.164lbaiayr) | M25: =_xlfn.CONCAT(L25,A25) -> force3ginsecticide(nysmaxrate0.164lbaiayr)100-1075 | N25: =IFERROR(VLOOKUP(LOWER(M25),file_list!$B:$B,1,FALSE),FALSE) -> force3ginsecticide(nysmaxrate0.164lbaiayr)100-1075 | O25: =IF(N25=FALSE,"FALSE","TRUE") -> TRUE
A26: 100-1084 | B26: FUSILADE II TURF AND ORNAMENTAL HERBICIDE (UNRESTRICTED 7/25/16) | C26: 100 | D26: REGISTERED | E26: 1288082 | F26: CLOSED | G26: ROUTINE | H26: 45604 | I26: KATHERINE HETTER | J26: HERBICIDE | K26: FALSE | L26: =SUBSTITUTE(LOWER(SUBSTITUTE(SUBSTITUTE(SUBSTITUTE(B26," ",""),"/",""),"&","")),"and","") -> fusiladeiiturfornamentalherbicide(unrestricted72516) | M26: =_xlfn.CONCAT(L26,A26) -> fusiladeiiturfornamentalherbicide(unrestricted72516)100-1084 | N26: =IFERROR(VLOOKUP(LOWER(M26),file_list!$B:$B,1,FALSE),FALSE) -> fusiladeiiturfornamentalherbicide(unrestricted72516)100-1084 | O26: =IF(N26=FALSE,"FALSE","TRUE") -> TRUE
A27: 100-1088 | B27: SCIMITAR GC INSECTICIDE (NO USE WITHIN 100' OF COASTAL MARSHES) | C27: 100 | D27: REGISTERED | E27: 1288082 | F27: CLOSED | G27: ROUTINE | H27: 45604 | I27: KATHERINE HETTER | J27: INSECTICIDE | K27: TRUE | L27: =SUBSTITUTE(LOWER(SUBSTITUTE(SUBSTITUTE(SUBSTITUTE(B27," ",""),"/",""),"&","")),"and","") -> scimitargcinsecticide(nousewithin100'ofcoastalmarshes) | M27: =_xlfn.CONCAT(L27,A27) -> scimitargcinsecticide(nousewithin100'ofcoastalmarshes)100-1088 | N27: =IFERROR(VLOOKUP(LOWER(M27),file_list!$B:$B,1,FALSE),FALSE) -> scimitargcinsecticide(nousewithin100'ofcoastalmarshes)100-1088 | O27: =IF(N27=FALSE,"FALSE","TRUE") -> TRUE
A28: 100-1093 | B28: HERITAGE FUNGICIDE (2EE - BROWN RING PATCH & RHIZOCTONIA LEAF AND SHEATH SPOT) | C28: 100 | D28: REGISTERED | E28: 18585 | F28: CLOSED | G28: 2EE | H28: 40319 | J28: FUNGICIDE | K28: FALSE | L28: =SUBSTITUTE(LOWER(SUBSTITUTE(SUBSTITUTE(SUBSTITUTE(B28," ",""),"/",""),"&","")),"and","") -> heritagefungicide(2ee-brownringpatchrhizoctonialeafsheathspot) | M28: =_xlfn.CONCAT(L28,A28) -> heritagefungicide(2ee-brownringpatchrhizoctonialeafsheathspot)100-1093 | N28: =IFERROR(VLOOKUP(LOWER(M28),file_list!$B:$B,1,FALSE),FALSE) -> heritagefungicide(2ee-brownringpatchrhizoctonialeafsheathspot)100-1093 | O28: =IF(N28=FALSE,"FALSE","TRUE") -> TRUE
A29: 100-1093 | B29: HERITAGE FUNGICIDE (2EE - PYTHIUM ROOT DYSFUNCTION) | C29: 100 | D29: REGISTERED | E29: 28211 | F29: CLOSED | G29: 2EE | H29: 41352 | J29: FUNGICIDE | K29: TRUE | L29: =SUBSTITUTE(LOWER(SUBSTITUTE(SUBSTITUTE(SUBSTITUTE(B29," ",""),"/",""),"&","")),"and","") -> heritagefungicide(2ee-pythiumrootdysfunction) | M29: =_xlfn.CONCAT(L29,A29) -> heritagefungicide(2ee-pythiumrootdysfunction)100-1093 | N29: =IFERROR(VLOOKUP(LOWER(M29),file_list!$B:$B,1,FALSE),FALSE) -> heritagefungicide(2ee-pythiumrootdysfunction)100-1093 | O29: =IF(N29=FALSE,"FALSE","TRUE") -> TRUE
A30: 100-1093 | B30: HERITAGE FUNGICIDE | C30: 100 | D30: REGISTERED | E30: 1288082 | F30: CLOSED | G30: ROUTINE | H30: 45604 | I30: KATHERINE HETTER | J30: FUNGICIDE | K30: TRUE | L30: =SUBSTITUTE(LOWER(SUBSTITUTE(SUBSTITUTE(SUBSTITUTE(B30," ",""),"/",""),"&","")),"and","") -> heritagefungicide | M30: =_xlfn.CONCAT(L30,A30) -> heritagefungicide100-1093 | N30: =IFERROR(VLOOKUP(LOWER(M30),file_list!$B:$B,1,FALSE),FALSE) -> heritagefungicide100-1093 | O30: =IF(N30=FALSE,"FALSE","TRUE") -> TRUE
A31: 100-1093 | B31: HERITAGE FUNGICIDE (2EE - CERCOSPORA LEAF SPOT) | C31: 100 | D31: REGISTERED | E31: 22802 | F31: CLOSED | G31: 2EE | H31: 40764 | J31: FUNGICIDE | K31: TRUE | L31: =SUBSTITUTE(LOWER(SUBSTITUTE(SUBSTITUTE(SUBSTITUTE(B31," ",""),"/",""),"&","")),"and","") -> heritagefungicide(2ee-cercosporaleafspot) | M31: =_xlfn.CONCAT(L31,A31) -> heritagefungicide(2ee-cercosporaleafspot)100-1093 | N31: =IFERROR(VLOOKUP(LOWER(M31),file_list!$B:$B,1,FALSE),FALSE) -> heritagefungicide(2ee-cercosporaleafspot)100-1093 | O31: =IF(N31=FALSE,"FALSE","TRUE") -> TRUE
A32: 100-1093 | B32: HERITAGE FUNGICIDE (2EE - DOWNY MILDEW) | C32: 100 | D32: REGISTERED | E32: 24110 | F32: CLOSED | G32: 2EE | H32: 40927 | J32: FUNGICIDE | K32: TRUE | L32: =SUBSTITUTE(LOWER(SUBSTITUTE(SUBSTITUTE(SUBSTITUTE(B32," ",""),"/",""),"&","")),"and","") -> heritagefungicide(2ee-downymildew) | M32: =_xlfn.CONCAT(L32,A32) -> heritagefungicide(2ee-downymildew)100-1093 | N32: =IFERROR(VLOOKUP(LOWER(M32),file_list!$B:$B,1,FALSE),FALSE) -> heritagefungicide(2ee-downymildew)100-1093 | O32: =IF(N32=FALSE,"FALSE","TRUE") -> TRUE
A33: 100-1098 | B33: QUADRIS FLOWABLE FUNGICIDE (2EE - REDUCED RATES) | C33: 100 | D33: REGISTERED | E33: 6740 | F33: CLOSED | G33: 2EE | H33: 39043 | J33: FUNGICIDE | K33: TRUE | L33: =SUBSTITUTE(LOWER(SUBSTITUTE(SUBSTITUTE(SUBSTITUTE(B33," ",""),"/",""),"&","")),"and","") -> quadrisflowablefungicide(2ee-reducedrates) | M33: =_xlfn.CONCAT(L33,A33) -> quadrisflowablefungicide(2ee-reducedrates)100-1098 | N33: =IFERROR(VLOOKUP(LOWER(M33),file_list!$B:$B,1,FALSE),FALSE) -> quadrisflowablefungicide(2ee-reducedrates)100-1098 | O33: =IF(N33=FALSE,"FALSE","TRUE") -> TRUE
A34: 100-1098 | B34: ABOUND FLOWABLE FUNGICIDE | C34: 100 | D34: DISCONTINUED | E34: 1288082 | F34: CLOSED | G34: ROUTINE | H34: 45604 | I34: KATHERINE HETTER | J34: FUNGICIDE | K34: TRUE | L34: =SUBSTITUTE(LOWER(SUBSTITUTE(SUBSTITUTE(SUBSTITUTE(B34," ",""),"/",""),"&","")),"and","") -> aboundflowablefungicide | M34: =_xlfn.CONCAT(L34,A34) -> aboundflowablefungicide100-1098 | N34: =IFERROR(VLOOKUP(LOWER(M34),file_list!$B:$B,1,FALSE),FALSE) -> aboundflowablefungicide100-1098 | O34: =IF(N34=FALSE,"FALSE","TRUE") -> TRUE
A35: 100-1098 | B35: QUADRIS FLOWABLE FUNGICIDE | C35: 100 | D35: REGISTERED | E35: 1288082 | F35: CLOSED | G35: ROUTINE | H35: 45604 | I35: KATHERINE HETTER | J35: FUNGICIDE | K35: TRUE | L35: =SUBSTITUTE(LOWER(SUBSTITUTE(SUBSTITUTE(SUBSTITUTE(B35," ",""),"/",""),"&","")),"and","") -> quadrisflowablefungicide | M35: =_xlfn.CONCAT(L35,A35) -> quadrisflowablefungicide100-1098 | N35: =IFERROR(VLOOKUP(LOWER(M35),file_list!$B:$B,1,FALSE),FALSE) -> quadrisflowablefungicide100-1098 | O35: =IF(N35=FALSE,"FALSE","TRUE") -> TRUE
A36: 100-1098 | B36: AFRAME | C36: 100 | D36: REGISTERED | E36: 1288082 | F36: CLOSED | G36: ROUTINE | H36: 45604 | I36: KATHERINE HETTER | J36: FUNGICIDE | K36: TRUE | L36: =SUBSTITUTE(LOWER(SUBSTITUTE(SUBSTITUTE(SUBSTITUTE(B36," ",""),"/",""),"&","")),"and","") -> aframe | M36: =_xlfn.CONCAT(L36,A36) -> aframe100-1098 | N36: =IFERROR(VLOOKUP(LOWER(M36),file_list!$B:$B,1,FALSE),FALSE) -> aframe100-1098 | O36: =IF(N36=FALSE,"FALSE","TRUE") -> TRUE
A37: 100-1101 | B37: FLEXSTAR | C37: 100 | D37: REGISTERED | E37: 1288082 | F37: CLOSED | G37: ROUTINE | H37: 45604 | I37: KATHERINE HETTER | J37: HERBICIDE | K37: TRUE | L37: =SUBSTITUTE(LOWER(SUBSTITUTE(SUBSTITUTE(SUBSTITUTE(B37," ",""),"/",""),"&","")),"and","") -> flexstar | M37: =_xlfn.CONCAT(L37,A37) -> flexstar100-1101 | N37: =IFERROR(VLOOKUP(LOWER(M37),file_list!$B:$B,1,FALSE),FALSE) -> flexstar100-1101 | O37: =IF(N37=FALSE,"FALSE","TRUE") -> TRUE
A38: 100-1101 | B38: SEDONA | C38: 100 | D38: REGISTERED | E38: 1288082 | F38: CLOSED | G38: ROUTINE | H38: 45604 | I38: KATHERINE HETTER | J38: HERBICIDE | K38: TRUE | L38: =SUBSTITUTE(LOWER(SUBSTITUTE(SUBSTITUTE(SUBSTITUTE(B38," ",""),"/",""),"&","")),"and","") -> sedona | M38: =_xlfn.CONCAT(L38,A38) -> sedona100-1101 | N38: =IFERROR(VLOOKUP(LOWER(M38),file_list!$B:$B,1,FALSE),FALSE) -> sedona100-1101 | O38: =IF(N38=FALSE,"FALSE","TRUE") -> TRUE
A39: 100-1111 | B39: ARCHER INSECT GROWTH REGULATOR (RESTRICTED USE AS OF 3/7/16) | C39: 100 | D39: REGISTERED | E39: 1288082 | F39: CLOSED | G39: ROUTINE | H39: 45604 | I39: KATHERINE HETTER | J39: GROWTH REGULATOR, MOSQUITO LARVICIDE | K39: FALSE | L39: =SUBSTITUTE(LOWER(SUBSTITUTE(SUBSTITUTE(SUBSTITUTE(B39," ",""),"/",""),"&","")),"and","") -> archerinsectgrowthregulator(restricteduseasof3716) | M39: =_xlfn.CONCAT(L39,A39) -> archerinsectgrowthregulator(restricteduseasof3716)100-1111 | N39: =IFERROR(VLOOKUP(LOWER(M39),file_list!$B:$B,1,FALSE),FALSE) -> archerinsectgrowthregulator(restricteduseasof3716)100-1111 | O39: =IF(N39=FALSE,"FALSE","TRUE") -> TRUE
A40: 100-1131 | B40: EXPLORER HERBICIDE | C40: 100 | D40: REGISTERED | E40: 1288082 | F40: CLOSED | G40: ROUTINE | H40: 45604 | I40: KATHERINE HETTER | J40: HERBICIDE | K40: TRUE | L40: =SUBSTITUTE(LOWER(SUBSTITUTE(SUBSTITUTE(SUBSTITUTE(B40," ",""),"/",""),"&","")),"and","") -> explorerherbicide | M40: =_xlfn.CONCAT(L40,A40) -> explorerherbicide100-1131 | N40: =IFERROR(VLOOKUP(LOWER(M40),file_list!$B:$B,1,FALSE),FALSE) -> explorerherbicide100-1131 | O40: =IF(N40=FALSE,"FALSE","TRUE") -> TRUE
...

Sheet Sheet2
A1: I found that the download script that makes the current products edited was not giving accurate
A2: is_PDF_downloaded
A3: true false
A4: a lot were false that were actually downloaded
A5: this was because the files had clean names but the lookup did not, so I made a few columns that substituted special characters to get it to lookup and give a correct true false

Sheet file_list
A1: File_Name | B1: Lower
A2: BIOGUARDMAINTAINBURNOUT35185-503 | B2: =SUBSTITUTE(LOWER(A2),"and","") -> bioguardmaintainburnout35185-503
A3: ProvectaAdvancedFORDOGS(5-10lbs)91384-3 | B3: =SUBSTITUTE(LOWER(A3),"and","") -> provectaadvancedfordogs(5-10lbs)91384-3
A4: SUPERSHOCK48520-20005 | B4: =SUBSTITUTE(LOWER(A4),"and","") -> supershock48520-20005
A5: PROKLEANRESTOREL87508-3-104210 | B5: =SUBSTITUTE(LOWER(A5),"and","") -> prokleanrestorel87508-3-104210
A6: lalguardm52gr64137-31 | B6: =SUBSTITUTE(LOWER(A6),"and","") -> lalguardm52gr64137-31
A7: PATHWAYHERBICIDE(NOSALE,USE,ORDISTRIBUTIONINLI)(RESTRICTED2407)62719-31 | B7: =SUBSTITUTE(LOWER(A7),"and","") -> pathwayherbicide(nosale,use,ordistributioninli)(restricted2407)62719-31
A8: ADVANTAGEXDSMALLCAT72642-11 | B8: =SUBSTITUTE(LOWER(A8),"and","") -> advantagexdsmallcat72642-11
A9: VECTOBACWDGBIOLOGICALLARVICIDE73049-56 | B9: =SUBSTITUTE(LOWER(A9),"and","") -> vectobacwdgbiologicallarvicide73049-56
A10: VARROXSAN94413-3 | B10: =SUBSTITUTE(LOWER(A10),"and","") -> varroxsan94413-3
A11: PRO-MIXhpoBIOFUNGICIDE+MYCORRHIZAE74267-8 | B11: =SUBSTITUTE(LOWER(A11),"and","") -> pro-mixhpobiofungicide+mycorrhizae74267-8
A12: LysolBrandKills99.9%ofVirusesandBacteriaDailyCleanser777-131 | B12: =SUBSTITUTE(LOWER(A12),"and","") -> lysolbrkills99.9%ofvirusesbacteriadailycleanser777-131
A13: ANUEW1001-91 | B13: =SUBSTITUTE(LOWER(A13),"and","") -> anuew1001-91
... A10000: EMPYROS[nosale,distribution,oruseinnassauandsuffolkcounties,NY]5905-641 | B10000: =SUBSTITUTE(LOWER(A10000),"and","") -> empyros[nosale,distribution,oruseinnassausuffolkcounties,ny]5905-641
